Workbook

Sheet Cover
B2: AURA WOMEN'S FASHION
B3: Sales & P&L Tracker — Reusable Template — FY 2026-27
B4: One tab per month · enter daily figures as they happen · Dashboard & FY Summary update automatically
B9: HOW TO USE THIS WORKBOOK
B10: 1. Open the tab for the current month (e.g. "October 2026").
B11: 2. Each day has one row. Type into the yellow cells only: Cash Sales, GPay Sales, Sales
B12: Return, Gross Profit, Electric Bill, Shop Rent, Shop Expense, Salary, Donation.
B13: 3. Total Sales, Total Expense, Net P&L and Margin % calculate themselves — never type into
B14: those columns.
B15: 4. That's it. The FY Summary tab and the Dashboard pull from every month tab automatically —
B16: nothing else to update by hand.
B17: 5. Months you haven't filled in yet show a trend-based estimate on the Dashboard/FY Summary,
... B20: CONTENTS
B21: Dashboard | C21: KPIs and full-year charts, always current
B22: FY Summary | C22: All 12 months rolled up, actual + auto-projected
B23: April 2026 … March 2027 | C23: One tab per month — this is where you enter data
B24: Data Quality Notes | C24: Issues found in the original data and how they were fixed
B25: README | C25: Full method notes

Sheet Dashboard
A1: AURA WOMEN'S FASHION — FY 2026-27 Performance Dashboard
A3: Live — pulls from FY Summary, which pulls from every month tab. Just enter data in the monthly tabs.
A5: FY Total Sales (12 mo) | D5: FY Net P&L (12 mo) | G5: Months Actual so far | J5: Avg FY Margin | M5: Best Month (Net P&L)
A6: ='FY Summary'!C18 -> 1466182 | D6: ='FY Summary'!F18 -> 133890.41 | G6: =COUNTIF('FY Summary'!B5:B16,"Actual")&" of 12" -> 12 of 12 | J6: ='FY Summary'!G18 -> 0.33996071 | M6: =INDEX('FY Summary'!A5:A16,MATCH(MAX('FY Summary'!F5:F16),'FY Summary'!F5:F16,0)) -> March 2027
A45: Dashed gold segments are projected months — they will turn solid maroon as you enter real data.

Sheet April 2026
A1: April 2026 — Daily Sales & P&L
A2: Sample data for this demo. Yellow cells are editable — swap in your own shop's numbers to reuse this template.
A4: Date | B4: Cash Sales | C4: GPay Sales | D4: Sales Return | E4: Credit Redeemed | F4: Total Sales | G4: Gross Profit | H4: Electric Bill | I4: Shop Rent | J4: Shop Expense | K4: Salary | L4: Donation | M4: Total Expense | N4: Net P&L | O4: Margin % | P4: Notes
A6: 46113 | B6: 624 | C6: 1761 | D6: 0 | E6: 0 | F6: =B6+C6+D6+E6 -> 2385 | G6: 771.44 | H6: 70 | I6: 330.63 | J6: 0 | K6: 684.46 | L6: 0 | M6: =SUM(H6:L6) -> 1085.09 | N6: =G6-M6 -> -313.65 | O6: =IFERROR(G6/F6,0) -> 0.32345493
A7: 46114 | B7: 1009 | C7: 2309 | D7: -661 | E7: 0 | F7: =B7+C7+D7+E7 -> 2657 | G7: 811.88 | H7: 70 | I7: 330.63 | J7: 0 | K7: 684.46 | L7: 0 | M7: =SUM(H7:L7) -> 1085.09 | N7: =G7-M7 -> -273.21 | O7: =IFERROR(G7/F7,0) -> 0.30556266
A8: 46115 | B8: 1387 | C8: 2100 | D8: 0 | E8: 0 | F8: =B8+C8+D8+E8 -> 3487 | G8: 1284.7 | H8: 70 | I8: 330.63 | J8: 0 | K8: 684.46 | L8: 0 | M8: =SUM(H8:L8) -> 1085.09 | N8: =G8-M8 -> 199.61 | O8: =IFERROR(G8/F8,0) -> 0.36842558
A9: 46116 | B9: 1042 | C9: 2234 | D9: 0 | E9: 0 | F9: =B9+C9+D9+E9 -> 3276 | G9: 1201.4 | H9: 70 | I9: 330.63 | J9: 0 | K9: 684.46 | L9: 0 | M9: =SUM(H9:L9) -> 1085.09 | N9: =G9-M9 -> 116.31 | O9: =IFERROR(G9/F9,0) -> 0.36672772
A10: 46117 | B10: 707 | C10: 1309 | D10: 0 | E10: 0 | F10: =B10+C10+D10+E10 -> 2016 | G10: 717.99 | H10: 70 | I10: 330.63 | J10: 0 | K10: 684.46 | L10: 63 | M10: =SUM(H10:L10) -> 1148.09 | N10: =G10-M10 -> -430.1 | O10: =IFERROR(G10/F10,0) -> 0.35614583
A11: 46118 | B11: 1095 | C11: 2222 | D11: 0 | E11: 0 | F11: =B11+C11+D11+E11 -> 3317 | G11: 1060.06 | H11: 70 | I11: 330.63 | J11: 0 | K11: 684.46 | L11: 0 | M11: =SUM(H11:L11) -> 1085.09 | N11: =G11-M11 -> -25.03 | O11: =IFERROR(G11/F11,0) -> 0.31958396
A12: 46119 | B12: 1177 | C12: 1850 | D12: 0 | E12: 0 | F12: =B12+C12+D12+E12 -> 3027 | G12: 1074.75 | H12: 70 | I12: 330.63 | J12: 0 | K12: 684.46 | L12: 0 | M12: =SUM(H12:L12) -> 1085.09 | N12: =G12-M12 -> -10.34 | O12: =IFERROR(G12/F12,0) -> 0.35505451
A13: 46120 | B13: 1130 | C13: 1964 | D13: 0 | E13: 0 | F13: =B13+C13+D13+E13 -> 3094 | G13: 942.05 | H13: 70 | I13: 330.63 | J13: 0 | K13: 684.46 | L13: 0 | M13: =SUM(H13:L13) -> 1085.09 | N13: =G13-M13 -> -143.04 | O13: =IFERROR(G13/F13,0) -> 0.30447641
A14: 46121 | B14: 703 | C14: 1564 | D14: 0 | E14: 0 | F14: =B14+C14+D14+E14 -> 2267 | G14: 692.1 | H14: 70 | I14: 330.63 | J14: 0 | K14: 684.46 | L14: 0 | M14: =SUM(H14:L14) -> 1085.09 | N14: =G14-M14 -> -392.99 | O14: =IFERROR(G14/F14,0) -> 0.30529334
A15: 46122 | B15: 1139 | C15: 2046 | D15: 0 | E15: 0 | F15: =B15+C15+D15+E15 -> 3185 | G15: 1009.68 | H15: 70 | I15: 330.63 | J15: 0 | K15: 684.46 | L15: 0 | M15: =SUM(H15:L15) -> 1085.09 | N15: =G15-M15 -> -75.41 | O15: =IFERROR(G15/F15,0) -> 0.31701099
A16: 46123 | B16: 1199 | C16: 2263 | D16: 0 | E16: 0 | F16: =B16+C16+D16+E16 -> 3462 | G16: 1078.17 | H16: 70 | I16: 330.63 | J16: 112 | K16: 684.46 | L16: 0 | M16: =SUM(H16:L16) -> 1197.09 | N16: =G16-M16 -> -118.92 | O16: =IFERROR(G16/F16,0) -> 0.31142981
A17: 46124 | B17: 958 | C17: 1687 | D17: 0 | E17: 0 | F17: =B17+C17+D17+E17 -> 2645 | G17: 884.16 | H17: 70 | I17: 330.63 | J17: 0 | K17: 684.46 | L17: 0 | M17: =SUM(H17:L17) -> 1085.09 | N17: =G17-M17 -> -200.93 | O17: =IFERROR(G17/F17,0) -> 0.33427599
... A25: 46132 | B25: 889 | C25: 2454 | D25: 0 | E25: 0 | F25: =B25+C25+D25+E25 -> 3343 | G25: 1170.13 | H25: 70 | I25: 330.63 | J25: 0 | K25: 684.46 | L25: 0 | M25: =SUM(H25:L25) -> 1085.09 | N25: =G25-M25 -> 85.04 | O25: =IFERROR(G25/F25,0) -> 0.35002393
A26: 46133 | B26: 0 | C26: 0 | D26: 0 | E26: 0 | F26: =B26+C26+D26+E26 -> 0 | G26: 0 | H26: 70 | I26: 330.63 | J26: 0 | K26: 0 | L26: 0 | M26: =SUM(H26:L26) -> 400.63 | N26: =G26-M26 -> -400.63 | O26: =IFERROR(G26/F26,0) -> 0 | P26: Shop closed
A27: 46134 | B27: 1119 | C27: 1727 | D27: 0 | E27: 0 | F27: =B27+C27+D27+E27 -> 2846 | G27: 1063.82 | H27: 70 | I27: 330.63 | J27: 0 | K27: 684.46 | L27: 0 | M27: =SUM(H27:L27) -> 1085.09 | N27: =G27-M27 -> -21.27 | O27: =IFERROR(G27/F27,0) -> 0.3737948
A28: 46135 | B28: 851 | C28: 1781 | D28: 0 | E28: 0 | F28: =B28+C28+D28+E28 -> 2632 | G28: 813.15 | H28: 70 | I28: 330.63 | J28: 0 | K28: 684.46 | L28: 0 | M28: =SUM(H28:L28) -> 1085.09 | N28: =G28-M28 -> -271.94 | O28: =IFERROR(G28/F28,0) -> 0.30894757
A29: 46136 | B29: 1272 | C29: 2156 | D29: 0 | E29: 0 | F29: =B29+C29+D29+E29 -> 3428 | G29: 1094.07 | H29: 70 | I29: 330.63 | J29: 0 | K29: 684.46 | L29: 0 | M29: =SUM(H29:L29) -> 1085.09 | N29: =G29-M29 -> 8.98 | O29: =IFERROR(G29/F29,0) -> 0.31915694
A30: 46137 | B30: 1184 | C30: 3339 | D30: 0 | E30: 0 | F30: =B30+C30+D30+E30 -> 4523 | G30: 1621.73 | H30: 70 | I30: 330.63 | J30: 0 | K30: 684.46 | L30: 0 | M30: =SUM(H30:L30) -> 1085.09 | N30: =G30-M30 -> 536.64 | O30: =IFERROR(G30/F30,0) -> 0.35855185
A31: 46138 | B31: 665 | C31: 1351 | D31: 0 | E31: 483 | F31: =B31+C31+D31+E31 -> 2499 | G31: 881.6 | H31: 70 | I31: 330.63 | J31: 0 | K31: 684.46 | L31: 0 | M31: =SUM(H31:L31) -> 1085.09 | N31: =G31-M31 -> -203.49 | O31: =IFERROR(G31/F31,0) -> 0.35278111
A32: 46139 | B32: 916 | C32: 1867 | D32: 0 | E32: 0 | F32: =B32+C32+D32+E32 -> 2783 | G32: 969.95 | H32: 70 | I32: 330.63 | J32: 0 | K32: 684.46 | L32: 0 | M32: =SUM(H32:L32) -> 1085.09 | N32: =G32-M32 -> -115.14 | O32: =IFERROR(G32/F32,0) -> 0.34852677
A33: 46140 | B33: 1000 | C33: 1752 | D33: 0 | E33: 0 | F33: =B33+C33+D33+E33 -> 2752 | G33: 977.48 | H33: 70 | I33: 330.63 | J33: 0 | K33: 684.46 | L33: 0 | M33: =SUM(H33:L33) -> 1085.09 | N33: =G33-M33 -> -107.61 | O33: =IFERROR(G33/F33,0) -> 0.35518895
A34: 46141 | B34: 957 | C34: 1772 | D34: 0 | E34: 0 | F34: =B34+C34+D34+E34 -> 2729 | G34: 900.23 | H34: 70 | I34: 330.63 | J34: 0 | K34: 684.46 | L34: 0 | M34: =SUM(H34:L34) -> 1085.09 | N34: =G34-M34 -> -184.86 | O34: =IFERROR(G34/F34,0) -> 0.32987541
A35: 46142 | B35: 750 | C35: 1862 | D35: 0 | E35: 0 | F35: =B35+C35+D35+E35 -> 2612 | G35: 796.98 | H35: 70 | I35: 330.63 | J35: 83 | K35: 684.46 | L35: 0 | M35: =SUM(H35:L35) -> 1168.09 | N35: =G35-M35 -> -371.11 | O35: =IFERROR(G35/F35,0) -> 0.30512251
A38: TOTAL | B38: =SUM(B6:B36) -> 29337 | C38: =SUM(C6:C36) -> 58665 | D38: =SUM(D6:D36) -> -661 | E38: =SUM(E6:E36) -> 483 | F38: =SUM(F6:F36) -> 87824 | G38: =SUM(G6:G36) -> 29566.02 | H38: =SUM(H6:H36) -> 2100 | I38: =SUM(I6:I36) -> 9918.9 | ... N38: =SUM(N6:N36) -> -2632.22 | O38: =IFERROR(G38/F38,0) -> 0.3366508

Sheet May 2026
A1: May 2026 — Daily Sales & P&L
A2: Sample data for this demo. Yellow cells are editable — swap in your own shop's numbers to reuse this template.
A4: Date | B4: Cash Sales | C4: GPay Sales | D4: Sales Return | E4: Credit Redeemed | F4: Total Sales | G4: Gross Profit | H4: Electric Bill | I4: Shop Rent | J4: Shop Expense | K4: Salary | L4: Donation | M4: Total Expense | N4: Net P&L | O4: Margin % | P4: Notes
A6: 46143 | B6: 1475 | C6: 4373 | D6: 0 | E6: 0 | F6: =B6+C6+D6+E6 -> 5848 | G6: 1798.03 | H6: 81.35 | I6: 296.64 | J6: 0 | K6: 608.12 | L6: 0 | M6: =SUM(H6:L6) -> 986.11 | N6: =G6-M6 -> 811.92 | O6: =IFERROR(G6/F6,0) -> 0.30746067
A7: 46144 | B7: 2001 | C7: 4434 | D7: 0 | E7: 0 | F7: =B7+C7+D7+E7 -> 6435 | G7: 2178.3 | H7: 81.35 | I7: 296.64 | J7: 0 | K7: 608.12 | L7: 0 | M7: =SUM(H7:L7) -> 986.11 | N7: =G7-M7 -> 1192.19 | O7: =IFERROR(G7/F7,0) -> 0.33850816
A8: 46145 | B8: 983 | C8: 2594 | D8: 0 | E8: 0 | F8: =B8+C8+D8+E8 -> 3577 | G8: 1073.72 | H8: 81.35 | I8: 296.64 | J8: 0 | K8: 608.12 | L8: 0 | M8: =SUM(H8:L8) -> 986.11 | N8: =G8-M8 -> 87.61 | O8: =IFERROR(G8/F8,0) -> 0.30017333
A9: 46146 | B9: 1728 | C9: 2970 | D9: 0 | E9: 0 | F9: =B9+C9+D9+E9 -> 4698 | G9: 1516.61 | H9: 81.35 | I9: 296.64 | J9: 0 | K9: 608.12 | L9: 0 | M9: =SUM(H9:L9) -> 986.11 | N9: =G9-M9 -> 530.5 | O9: =IFERROR(G9/F9,0) -> 0.32282035
A10: 46147 | B10: 1774 | C10: 3052 | D10: 0 | E10: 0 | F10: =B10+C10+D10+E10 -> 4826 | G10: 1703.34 | H10: 81.35 | I10: 296.64 | J10: 0 | K10: 608.12 | L10: 0 | M10: =SUM(H10:L10) -> 986.11 | N10: =G10-M10 -> 717.23 | O10: =IFERROR(G10/F10,0) -> 0.35295068
A11: 46148 | B11: 1487 | C11: 3774 | D11: 0 | E11: 0 | F11: =B11+C11+D11+E11 -> 5261 | G11: 1602.91 | H11: 81.35 | I11: 296.64 | J11: 0 | K11: 608.12 | L11: 31 | M11: =SUM(H11:L11) -> 1017.11 | N11: =G11-M11 -> 585.8 | O11: =IFERROR(G11/F11,0) -> 0.30467782
A12: 46149 | B12: 1452 | C12: 4186 | D12: 0 | E12: 0 | F12: =B12+C12+D12+E12 -> 5638 | G12: 1906.45 | H12: 81.35 | I12: 296.64 | J12: 0 | K12: 608.12 | L12: 0 | M12: =SUM(H12:L12) -> 986.11 | N12: =G12-M12 -> 920.34 | O12: =IFERROR(G12/F12,0) -> 0.33814296
A13: 46150 | B13: 1715 | C13: 4918 | D13: 0 | E13: 0 | F13: =B13+C13+D13+E13 -> 6633 | G13: 2259.37 | H13: 81.35 | I13: 296.64 | J13: 0 | K13: 608.12 | L13: 7 | M13: =SUM(H13:L13) -> 993.11 | N13: =G13-M13 -> 1266.26 | O13: =IFERROR(G13/F13,0) -> 0.34062566
A14: 46151 | B14: 2112 | C14: 3456 | D14: 0 | E14: 0 | F14: =B14+C14+D14+E14 -> 5568 | G14: 1850.26 | H14: 81.35 | I14: 296.64 | J14: 0 | K14: 608.12 | L14: 0 | M14: =SUM(H14:L14) -> 986.11 | N14: =G14-M14 -> 864.15 | O14: =IFERROR(G14/F14,0) -> 0.33230244
A15: 46152 | B15: 1337 | C15: 2632 | D15: 0 | E15: 0 | F15: =B15+C15+D15+E15 -> 3969 | G15: 1203.32 | H15: 81.35 | I15: 296.64 | J15: 99 | K15: 608.12 | L15: 0 | M15: =SUM(H15:L15) -> 1085.11 | N15: =G15-M15 -> 118.21 | O15: =IFERROR(G15/F15,0) -> 0.30317964
A16: 46153 | B16: 1342 | C16: 3171 | D16: 0 | E16: 0 | F16: =B16+C16+D16+E16 -> 4513 | G16: 1448.05 | H16: 81.35 | I16: 296.64 | J16: 0 | K16: 608.12 | L16: 0 | M16: =SUM(H16:L16) -> 986.11 | N16: =G16-M16 -> 461.94 | O16: =IFERROR(G16/F16,0) -> 0.32086195
A17: 46154 | B17: 1094 | C17: 2679 | D17: 0 | E17: 0 | F17: =B17+C17+D17+E17 -> 3773 | G17: 1171.4 | H17: 81.35 | I17: 296.64 | J17: 0 | K17: 608.12 | L17: 0 | M17: =SUM(H17:L17) -> 986.11 | N17: =G17-M17 -> 185.29 | O17: =IFERROR(G17/F17,0) -> 0.31046912
... A32: 46169 | B32: 1395 | C32: 2589 | D32: 0 | E32: 0 | F32: =B32+C32+D32+E32 -> 3984 | G32: 1307.92 | H32: 81.35 | I32: 296.64 | J32: 0 | K32: 608.12 | L32: 0 | M32: =SUM(H32:L32) -> 986.11 | N32: =G32-M32 -> 321.81 | O32: =IFERROR(G32/F32,0) -> 0.32829317
A33: 46170 | B33: 0 | C33: 0 | D33: 0 | E33: 0 | F33: =B33+C33+D33+E33 -> 0 | G33: 0 | H33: 81.35 | I33: 296.64 | J33: 0 | K33: 0 | L33: 0 | M33: =SUM(H33:L33) -> 377.99 | N33: =G33-M33 -> -377.99 | O33: =IFERROR(G33/F33,0) -> 0 | P33: Shop closed
A34: 46171 | B34: 2166 | C34: 5420 | D34: -590 | E34: 0 | F34: =B34+C34+D34+E34 -> 6996 | G34: 2546.48 | H34: 81.35 | I34: 296.64 | J34: 0 | K34: 608.12 | L34: 0 | M34: =SUM(H34:L34) -> 986.11 | N34: =G34-M34 -> 1560.37 | O34: =IFERROR(G34/F34,0) -> 0.36399085
A35: 46172 | B35: 1394 | C35: 3639 | D35: 0 | E35: 0 | F35: =B35+C35+D35+E35 -> 5033 | G35: 1882.14 | H35: 81.35 | I35: 296.64 | J35: 0 | K35: 608.12 | L35: 0 | M35: =SUM(H35:L35) -> 986.11 | N35: =G35-M35 -> 896.03 | O35: =IFERROR(G35/F35,0) -> 0.37395986
A36: 46173 | B36: 1627 | C36: 3016 | D36: 0 | E36: 0 | F36: =B36+C36+D36+E36 -> 4643 | G36: 1665.93 | H36: 81.35 | I36: 296.64 | J36: 0 | K36: 608.12 | L36: 0 | M36: =SUM(H36:L36) -> 986.11 | N36: =G36-M36 -> 679.82 | O36: =IFERROR(G36/F36,0) -> 0.35880465
A38: TOTAL | B38: =SUM(B6:B36) -> 48060 | C38: =SUM(C6:C36) -> 103940 | D38: =SUM(D6:D36) -> -590 | E38: =SUM(E6:E36) -> 425 | F38: =SUM(F6:F36) -> 151835 | G38: =SUM(G6:G36) -> 51201.26 | H38: =SUM(H6:H36) -> 2521.85 | I38: =SUM(I6:I36) -> 9195.84 | ... N38: =SUM(N6:N36) -> 20707.97 | O38: =IFERROR(G38/F38,0) -> 0.33721645

Sheet June 2026
A1: June 2026 — Daily Sales & P&L
A2: Sample data for this demo. Yellow cells are editable — swap in your own shop's numbers to reuse this template.
A4: Date | B4: Cash Sales | C4: GPay Sales | D4: Sales Return | E4: Credit Redeemed | F4: Total Sales | G4: Gross Profit | H4: Electric Bill | I4: Shop Rent | J4: Shop Expense | K4: Salary | L4: Donation | M4: Total Expense | N4: Net P&L | O4: Margin % | P4: Notes
A6: 46174 | B6: 613 | C6: 1449 | D6: 0 | E6: 0 | F6: =B6+C6+D6+E6 -> 2062 | G6: 758.49 | H6: 84.38 | I6: 304.67 | J6: 0 | K6: 566.04 | L6: 0 | M6: =SUM(H6:L6) -> 955.09 | N6: =G6-M6 -> -196.6 | O6: =IFERROR(G6/F6,0) -> 0.3678419
A7: 46175 | B7: 790 | C7: 1877 | D7: 0 | E7: 0 | F7: =B7+C7+D7+E7 -> 2667 | G7: 887.23 | H7: 84.38 | I7: 304.67 | J7: 0 | K7: 566.04 | L7: 0 | M7: =SUM(H7:L7) -> 955.09 | N7: =G7-M7 -> -67.86 | O7: =IFERROR(G7/F7,0) -> 0.33266967
A8: 46176 | B8: 749 | C8: 2034 | D8: 0 | E8: 0 | F8: =B8+C8+D8+E8 -> 2783 | G8: 928.51 | H8: 84.38 | I8: 304.67 | J8: 0 | K8: 566.04 | L8: 0 | M8: =SUM(H8:L8) -> 955.09 | N8: =G8-M8 -> -26.58 | O8: =IFERROR(G8/F8,0) -> 0.33363636
A9: 46177 | B9: 774 | C9: 1233 | D9: 0 | E9: 0 | F9: =B9+C9+D9+E9 -> 2007 | G9: 700.93 | H9: 84.38 | I9: 304.67 | J9: 0 | K9: 566.04 | L9: 0 | M9: =SUM(H9:L9) -> 955.09 | N9: =G9-M9 -> -254.16 | O9: =IFERROR(G9/F9,0) -> 0.34924265
A10: 46178 | B10: 815 | C10: 2446 | D10: 0 | E10: 0 | F10: =B10+C10+D10+E10 -> 3261 | G10: 1053.15 | H10: 84.38 | I10: 304.67 | J10: 0 | K10: 566.04 | L10: 0 | M10: =SUM(H10:L10) -> 955.09 | N10: =G10-M10 -> 98.06 | O10: =IFERROR(G10/F10,0) -> 0.32295308
A11: 46179 | B11: 1007 | C11: 1886 | D11: 0 | E11: 0 | F11: =B11+C11+D11+E11 -> 2893 | G11: 975.52 | H11: 84.38 | I11: 304.67 | J11: 0 | K11: 566.04 | L11: 0 | M11: =SUM(H11:L11) -> 955.09 | N11: =G11-M11 -> 20.43 | O11: =IFERROR(G11/F11,0) -> 0.33720014
A12: 46180 | B12: 764 | C12: 1615 | D12: 0 | E12: 0 | F12: =B12+C12+D12+E12 -> 2379 | G12: 885.21 | H12: 84.38 | I12: 304.67 | J12: 0 | K12: 566.04 | L12: 0 | M12: =SUM(H12:L12) -> 955.09 | N12: =G12-M12 -> -69.88 | O12: =IFERROR(G12/F12,0) -> 0.37209332
A13: 46181 | B13: 603 | C13: 1694 | D13: 0 | E13: 0 | F13: =B13+C13+D13+E13 -> 2297 | G13: 783.82 | H13: 84.38 | I13: 304.67 | J13: 0 | K13: 566.04 | L13: 0 | M13: =SUM(H13:L13) -> 955.09 | N13: =G13-M13 -> -171.27 | O13: =IFERROR(G13/F13,0) -> 0.3412364
A14: 46182 | B14: 1025 | C14: 1726 | D14: 0 | E14: 0 | F14: =B14+C14+D14+E14 -> 2751 | G14: 990.61 | H14: 84.38 | I14: 304.67 | J14: 0 | K14: 566.04 | L14: 0 | M14: =SUM(H14:L14) -> 955.09 | N14: =G14-M14 -> 35.52 | O14: =IFERROR(G14/F14,0) -> 0.36009088
A15: 46183 | B15: 510 | C15: 1312 | D15: 0 | E15: 0 | F15: =B15+C15+D15+E15 -> 1822 | G15: 550.16 | H15: 84.38 | I15: 304.67 | J15: 0 | K15: 566.04 | L15: 0 | M15: =SUM(H15:L15) -> 955.09 | N15: =G15-M15 -> -404.93 | O15: =IFERROR(G15/F15,0) -> 0.3019539
A16: 46184 | B16: 1052 | C16: 1735 | D16: 0 | E16: 0 | F16: =B16+C16+D16+E16 -> 2787 | G16: 852.34 | H16: 84.38 | I16: 304.67 | J16: 0 | K16: 566.04 | L16: 0 | M16: =SUM(H16:L16) -> 955.09 | N16: =G16-M16 -> -102.75 | O16: =IFERROR(G16/F16,0) -> 0.30582705
A17: 46185 | B17: 714 | C17: 1842 | D17: -1871 | E17: 0 | F17: =B17+C17+D17+E17 -> 685 | G17: 232.59 | H17: 84.38 | I17: 304.67 | J17: 0 | K17: 566.04 | L17: 0 | M17: =SUM(H17:L17) -> 955.09 | N17: =G17-M17 -> -722.5 | O17: =IFERROR(G17/F17,0) -> 0.33954745
A18: 46186 | B18: 0 | C18: 0 | D18: 0 | E18: 0 | F18: =B18+C18+D18+E18 -> 0 | G18: 0 | H18: 84.38 | I18: 304.67 | J18: 0 | K18: 0 | L18: 0 | M18: =SUM(H18:L18) -> 389.05 | N18: =G18-M18 -> -389.05 | O18: =IFERROR(G18/F18,0) -> 0 | P18: Shop closed
A19: 46187 | B19: 450 | C19: 1243 | D19: 0 | E19: 0 | F19: =B19+C19+D19+E19 -> 1693 | G19: 565.48 | H19: 84.38 | I19: 304.67 | J19: 0 | K19: 566.04 | L19: 0 | M19: =SUM(H19:L19) -> 955.09 | N19: =G19-M19 -> -389.61 | O19: =IFERROR(G19/F19,0) -> 0.33401063
A20: 46188 | B20: 594 | C20: 1220 | D20: 0 | E20: 0 | F20: =B20+C20+D20+E20 -> 1814 | G20: 551.49 | H20: 84.38 | I20: 304.67 | J20: 0 | K20: 566.04 | L20: 0 | M20: =SUM(H20:L20) -> 955.09 | N20: =G20-M20 -> -403.6 | O20: =IFERROR(G20/F20,0) -> 0.30401874
A21: 46189 | B21: 695 | C21: 1487 | D21: 0 | E21: 2274 | F21: =B21+C21+D21+E21 -> 4456 | G21: 1574.78 | H21: 84.38 | I21: 304.67 | J21: 0 | K21: 566.04 | L21: 0 | M21: =SUM(H21:L21) -> 955.09 | N21: =G21-M21 -> 619.69 | O21: =IFERROR(G21/F21,0) -> 0.35340664
A22: 46190 | B22: 987 | C22: 1527 | D22: 0 | E22: 0 | F22: =B22+C22+D22+E22 -> 2514 | G22: 933.48 | H22: 84.38 | I22: 304.67 | J22: 0 | K22: 566.04 | L22: 0 | M22: =SUM(H22:L22) -> 955.09 | N22: =G22-M22 -> -21.61 | O22: =IFERROR(G22/F22,0) -> 0.37131265
A23: 46191 | B23: 666 | C23: 1380 | D23: 0 | E23: 0 | F23: =B23+C23+D23+E23 -> 2046 | G23: 749.75 | H23: 84.38 | I23: 304.67 | J23: 0 | K23: 566.04 | L23: 0 | M23: =SUM(H23:L23) -> 955.09 | N23: =G23-M23 -> -205.34 | O23: =IFERROR(G23/F23,0) -> 0.36644673
A24: 46192 | B24: 1159 | C24: 2048 | D24: 0 | E24: 0 | F24: =B24+C24+D24+E24 -> 3207 | G24: 1083.88 | H24: 84.38 | I24: 304.67 | J24: 0 | K24: 566.04 | L24: 0 | M24: =SUM(H24:L24) -> 955.09 | N24: =G24-M24 -> 128.79 | O24: =IFERROR(G24/F24,0) -> 0.33797318
A25: 46193 | B25: 1059 | C25: 2004 | D25: 0 | E25: 0 | F25: =B25+C25+D25+E25 -> 3063 | G25: 1106.55 | H25: 84.38 | I25: 304.67 | J25: 0 | K25: 566.04 | L25: 0 | M25: =SUM(H25:L25) -> 955.09 | N25: =G25-M25 -> 151.46 | O25: =IFERROR(G25/F25,0) -> 0.36126347
A26: 46194 | B26: 526 | C26: 1281 | D26: 0 | E26: 0 | F26: =B26+C26+D26+E26 -> 1807 | G26: 553.3 | H26: 84.38 | I26: 304.67 | J26: 0 | K26: 566.04 | L26: 0 | M26: =SUM(H26:L26) -> 955.09 | N26: =G26-M26 -> -401.79 | O26: =IFERROR(G26/F26,0) -> 0.30619812
A27: 46195 | B27: 698 | C27: 1644 | D27: 0 | E27: 0 | F27: =B27+C27+D27+E27 -> 2342 | G27: 803.8 | H27: 84.38 | I27: 304.67 | J27: 35 | K27: 566.04 | L27: 0 | M27: =SUM(H27:L27) -> 990.09 | N27: =G27-M27 -> -186.29 | O27: =IFERROR(G27/F27,0) -> 0.34321093
A28: 46196 | B28: 704 | C28: 1275 | D28: 0 | E28: 0 | F28: =B28+C28+D28+E28 -> 1979 | G28: 603.87 | H28: 84.38 | I28: 304.67 | J28: 0 | K28: 566.04 | L28: 0 | M28: =SUM(H28:L28) -> 955.09 | N28: =G28-M28 -> -351.22 | O28: =IFERROR(G28/F28,0) -> 0.30513896
A29: 46197 | B29: 778 | C29: 1713 | D29: 0 | E29: 0 | F29: =B29+C29+D29+E29 -> 2491 | G29: 788.52 | H29: 84.38 | I29: 304.67 | J29: 0 | K29: 566.04 | L29: 0 | M29: =SUM(H29:L29) -> 955.09 | N29: =G29-M29 -> -166.57 | O29: =IFERROR(G29/F29,0) -> 0.31654757
A30: 46198 | B30: 572 | C30: 1122 | D30: 0 | E30: 0 | F30: =B30+C30+D30+E30 -> 1694 | G30: 602.46 | H30: 84.38 | I30: 304.67 | J30: 0 | K30: 566.04 | L30: 0 | M30: =SUM(H30:L30) -> 955.09 | N30: =G30-M30 -> -352.63 | O30: =IFERROR(G30/F30,0) -> 0.35564345
... A35: 46203 | B35: 760 | C35: 1688 | D35: 0 | E35: 0 | F35: =B35+C35+D35+E35 -> 2448 | G35: 766.72 | H35: 84.38 | I35: 304.67 | J35: 0 | K35: 566.04 | L35: 0 | M35: =SUM(H35:L35) -> 955.09 | N35: =G35-M35 -> -188.37 | O35: =IFERROR(G35/F35,0) -> 0.31320261
A38: TOTAL | B38: =SUM(B6:B36) -> 22875 | C38: =SUM(C6:C36) -> 48125 | D38: =SUM(D6:D36) -> -1871 | E38: =SUM(E6:E36) -> 2274 | F38: =SUM(F6:F36) -> 71403 | G38: =SUM(G6:G36) -> 24066.21 | H38: =SUM(H6:H36) -> 2531.4 | I38: =SUM(I6:I36) -> 9140.1 | ... N38: =SUM(N6:N36) -> -4055.45 | O38: =IFERROR(G38/F38,0) -> 0.3370476

Sheet July 2026
A1: July 2026 — Daily Sales & P&L
A2: Sample data for this demo. Yellow cells are editable — swap in your own shop's numbers to reuse this template.
A4: Date | B4: Cash Sales | C4: GPay Sales | D4: Sales Return | E4: Credit Redeemed | F4: Total Sales | G4: Gross Profit | H4: Electric Bill | I4: Shop Rent | J4: Shop Expense | K4: Salary | L4: Donation | M4: Total Expense | N4: Net P&L | O4: Margin % | P4: Notes
A6: 46204 | B6: 1308 | C6: 2080 | D6: 0 | E6: 0 | F6: =B6+C6+D6+E6 -> 3388 | G6: 1118.12 | H6: 88.49 | I6: 327.66 | J6: 0 | K6: 615.16 | L6: 0 | M6: =SUM(H6:L6) -> 1031.31 | N6: =G6-M6 -> 86.81 | O6: =IFERROR(G6/F6,0) -> 0.33002361
A7: 46205 | B7: 1079 | C7: 2106 | D7: 0 | E7: 0 | F7: =B7+C7+D7+E7 -> 3185 | G7: 1167.13 | H7: 88.49 | I7: 327.66 | J7: 0 | K7: 615.16 | L7: 0 | M7: =SUM(H7:L7) -> 1031.31 | N7: =G7-M7 -> 135.82 | O7: =IFERROR(G7/F7,0) -> 0.36644584
A8: 46206 | B8: 1644 | C8: 3924 | D8: 0 | E8: 0 | F8: =B8+C8+D8+E8 -> 5568 | G8: 1975.2 | H8: 88.49 | I8: 327.66 | J8: 0 | K8: 615.16 | L8: 0 | M8: =SUM(H8:L8) -> 1031.31 | N8: =G8-M8 -> 943.89 | O8: =IFERROR(G8/F8,0) -> 0.35474138
A9: 46207 | B9: 1393 | C9: 2768 | D9: 0 | E9: 259 | F9: =B9+C9+D9+E9 -> 4420 | G9: 1514.38 | H9: 88.49 | I9: 327.66 | J9: 0 | K9: 615.16 | L9: 65 | M9: =SUM(H9:L9) -> 1096.31 | N9: =G9-M9 -> 418.07 | O9: =IFERROR(G9/F9,0) -> 0.34261991
A10: 46208 | B10: 910 | C10: 2701 | D10: 0 | E10: 0 | F10: =B10+C10+D10+E10 -> 3611 | G10: 1204.65 | H10: 88.49 | I10: 327.66 | J10: 0 | K10: 615.16 | L10: 0 | M10: =SUM(H10:L10) -> 1031.31 | N10: =G10-M10 -> 173.34 | O10: =IFERROR(G10/F10,0) -> 0.33360565
A11: 46209 | B11: 1014 | C11: 2317 | D11: 0 | E11: 0 | F11: =B11+C11+D11+E11 -> 3331 | G11: 1236.89 | H11: 88.49 | I11: 327.66 | J11: 0 | K11: 615.16 | L11: 0 | M11: =SUM(H11:L11) -> 1031.31 | N11: =G11-M11 -> 205.58 | O11: =IFERROR(G11/F11,0) -> 0.37132693
A12: 46210 | B12: 0 | C12: 0 | D12: 0 | E12: 0 | F12: =B12+C12+D12+E12 -> 0 | G12: 0 | H12: 88.49 | I12: 327.66 | J12: 0 | K12: 0 | L12: 0 | M12: =SUM(H12:L12) -> 416.15 | N12: =G12-M12 -> -416.15 | O12: =IFERROR(G12/F12,0) -> 0 | P12: Shop closed
A13: 46211 | B13: 1169 | C13: 2246 | D13: 0 | E13: 0 | F13: =B13+C13+D13+E13 -> 3415 | G13: 1275.74 | H13: 88.49 | I13: 327.66 | J13: 0 | K13: 615.16 | L13: 0 | M13: =SUM(H13:L13) -> 1031.31 | N13: =G13-M13 -> 244.43 | O13: =IFERROR(G13/F13,0) -> 0.37356955
A14: 46212 | B14: 1457 | C14: 2441 | D14: 0 | E14: 0 | F14: =B14+C14+D14+E14 -> 3898 | G14: 1354.16 | H14: 88.49 | I14: 327.66 | J14: 0 | K14: 615.16 | L14: 0 | M14: =SUM(H14:L14) -> 1031.31 | N14: =G14-M14 -> 322.85 | O14: =IFERROR(G14/F14,0) -> 0.34739867
A15: 46213 | B15: 1417 | C15: 2215 | D15: 0 | E15: 0 | F15: =B15+C15+D15+E15 -> 3632 | G15: 1170.65 | H15: 88.49 | I15: 327.66 | J15: 0 | K15: 615.16 | L15: 0 | M15: =SUM(H15:L15) -> 1031.31 | N15: =G15-M15 -> 139.34 | O15: =IFERROR(G15/F15,0) -> 0.32231553
A16: 46214 | B16: 1925 | C16: 3812 | D16: -1804 | E16: 0 | F16: =B16+C16+D16+E16 -> 3933 | G16: 1285.74 | H16: 88.49 | I16: 327.66 | J16: 0 | K16: 615.16 | L16: 0 | M16: =SUM(H16:L16) -> 1031.31 | N16: =G16-M16 -> 254.43 | O16: =IFERROR(G16/F16,0) -> 0.32691076
A17: 46215 | B17: 821 | C17: 1719 | D17: 0 | E17: 0 | F17: =B17+C17+D17+E17 -> 2540 | G17: 834.1 | H17: 88.49 | I17: 327.66 | J17: 0 | K17: 615.16 | L17: 0 | M17: =SUM(H17:L17) -> 1031.31 | N17: =G17-M17 -> -197.21 | O17: =IFERROR(G17/F17,0) -> 0.32838583
A18: 46216 | B18: 923 | C18: 1796 | D18: 0 | E18: 0 | F18: =B18+C18+D18+E18 -> 2719 | G18: 1007.14 | H18: 88.49 | I18: 327.66 | J18: 0 | K18: 615.16 | L18: 0 | M18: =SUM(H18:L18) -> 1031.31 | N18: =G18-M18 -> -24.17 | O18: =IFERROR(G18/F18,0) -> 0.37040824
A19: 46217 | B19: 1187 | C19: 3072 | D19: 0 | E19: 0 | F19: =B19+C19+D19+E19 -> 4259 | G19: 1359.93 | H19: 88.49 | I19: 327.66 | J19: 0 | K19: 615.16 | L19: 0 | M19: =SUM(H19:L19) -> 1031.31 | N19: =G19-M19 -> 328.62 | O19: =IFERROR(G19/F19,0) -> 0.31930735
A20: 46218 | B20: 764 | C20: 1906 | D20: 0 | E20: 0 | F20: =B20+C20+D20+E20 -> 2670 | G20: 902.69 | H20: 88.49 | I20: 327.66 | J20: 0 | K20: 615.16 | L20: 0 | M20: =SUM(H20:L20) -> 1031.31 | N20: =G20-M20 -> -128.62 | O20: =IFERROR(G20/F20,0) -> 0.33808614
A21: 46219 | B21: 670 | C21: 1984 | D21: 0 | E21: 0 | F21: =B21+C21+D21+E21 -> 2654 | G21: 858.67 | H21: 88.49 | I21: 327.66 | J21: 0 | K21: 615.16 | L21: 0 | M21: =SUM(H21:L21) -> 1031.31 | N21: =G21-M21 -> -172.64 | O21: =IFERROR(G21/F21,0) -> 0.32353806
A22: 46220 | B22: 1429 | C22: 2660 | D22: 0 | E22: 0 | F22: =B22+C22+D22+E22 -> 4089 | G22: 1347.41 | H22: 88.49 | I22: 327.66 | J22: 0 | K22: 615.16 | L22: 0 | M22: =SUM(H22:L22) -> 1031.31 | N22: =G22-M22 -> 316.1 | O22: =IFERROR(G22/F22,0) -> 0.32952067
A23: 46221 | B23: 2187 | C23: 3287 | D23: 0 | E23: 0 | F23: =B23+C23+D23+E23 -> 5474 | G23: 1883.23 | H23: 88.49 | I23: 327.66 | J23: 0 | K23: 615.16 | L23: 0 | M23: =SUM(H23:L23) -> 1031.31 | N23: =G23-M23 -> 851.92 | O23: =IFERROR(G23/F23,0) -> 0.34403179
A24: 46222 | B24: 925 | C24: 2200 | D24: 0 | E24: 0 | F24: =B24+C24+D24+E24 -> 3125 | G24: 995.13 | H24: 88.49 | I24: 327.66 | J24: 0 | K24: 615.16 | L24: 0 | M24: =SUM(H24:L24) -> 1031.31 | N24: =G24-M24 -> -36.18 | O24: =IFERROR(G24/F24,0) -> 0.3184416
... A36: 46234 | B36: 1504 | C36: 2389 | D36: 0 | E36: 0 | F36: =B36+C36+D36+E36 -> 3893 | G36: 1260.51 | H36: 88.49 | I36: 327.66 | J36: 0 | K36: 615.16 | L36: 0 | M36: =SUM(H36:L36) -> 1031.31 | N36: =G36-M36 -> 229.2 | O36: =IFERROR(G36/F36,0) -> 0.32378885
A38: TOTAL | B38: =SUM(B6:B36) -> 37018 | C38: =SUM(C6:C36) -> 74980 | D38: =SUM(D6:D36) -> -1804 | E38: =SUM(E6:E36) -> 259 | F38: =SUM(F6:F36) -> 110453 | G38: =SUM(G6:G36) -> 37272.54 | H38: =SUM(H6:H36) -> 2743.19 | I38: =SUM(I6:I36) -> 10157.46 | ... N38: =SUM(N6:N36) -> 5776.09 | O38: =IFERROR(G38/F38,0) -> 0.33745159

Sheet August 2026
A1: August 2026 — Daily Sales & P&L
A2: Sample data for this demo. Yellow cells are editable — swap in your own shop's numbers to reuse this template.
A4: Date | B4: Cash Sales | C4: GPay Sales | D4: Sales Return | E4: Credit Redeemed | F4: Total Sales | G4: Gross Profit | H4: Electric Bill | I4: Shop Rent | J4: Shop Expense | K4: Salary | L4: Donation | M4: Total Expense | N4: Net P&L | O4: Margin % | P4: Notes
A6: 46235 | B6: 1157 | C6: 2865 | D6: 0 | E6: 0 | F6: =B6+C6+D6+E6 -> 4022 | G6: 1235.99 | H6: 75.67 | I6: 292.89 | J6: 0 | K6: 564.46 | L6: 0 | M6: =SUM(H6:L6) -> 933.02 | N6: =G6-M6 -> 302.97 | O6: =IFERROR(G6/F6,0) -> 0.30730731
A7: 46236 | B7: 1105 | C7: 2182 | D7: 0 | E7: 0 | F7: =B7+C7+D7+E7 -> 3287 | G7: 1236.12 | H7: 75.67 | I7: 292.89 | J7: 0 | K7: 564.46 | L7: 0 | M7: =SUM(H7:L7) -> 933.02 | N7: =G7-M7 -> 303.1 | O7: =IFERROR(G7/F7,0) -> 0.37606328
A8: 46237 | B8: 1206 | C8: 2945 | D8: -297 | E8: 0 | F8: =B8+C8+D8+E8 -> 3854 | G8: 1389.37 | H8: 75.67 | I8: 292.89 | J8: 0 | K8: 564.46 | L8: 0 | M8: =SUM(H8:L8) -> 933.02 | N8: =G8-M8 -> 456.35 | O8: =IFERROR(G8/F8,0) -> 0.36050078
A9: 46238 | B9: 1376 | C9: 2175 | D9: 0 | E9: 0 | F9: =B9+C9+D9+E9 -> 3551 | G9: 1116.86 | H9: 75.67 | I9: 292.89 | J9: 0 | K9: 564.46 | L9: 0 | M9: =SUM(H9:L9) -> 933.02 | N9: =G9-M9 -> 183.84 | O9: =IFERROR(G9/F9,0) -> 0.31451985
A10: 46239 | B10: 1111 | C10: 2321 | D10: 0 | E10: 0 | F10: =B10+C10+D10+E10 -> 3432 | G10: 1054.65 | H10: 75.67 | I10: 292.89 | J10: 0 | K10: 564.46 | L10: 0 | M10: =SUM(H10:L10) -> 933.02 | N10: =G10-M10 -> 121.63 | O10: =IFERROR(G10/F10,0) -> 0.30729895
A11: 46240 | B11: 0 | C11: 0 | D11: 0 | E11: 0 | F11: =B11+C11+D11+E11 -> 0 | G11: 0 | H11: 75.67 | I11: 292.89 | J11: 0 | K11: 0 | L11: 0 | M11: =SUM(H11:L11) -> 368.56 | N11: =G11-M11 -> -368.56 | O11: =IFERROR(G11/F11,0) -> 0 | P11: Shop closed
A12: 46241 | B12: 2087 | C12: 3809 | D12: 0 | E12: 0 | F12: =B12+C12+D12+E12 -> 5896 | G12: 1904.75 | H12: 75.67 | I12: 292.89 | J12: 0 | K12: 564.46 | L12: 0 | M12: =SUM(H12:L12) -> 933.02 | N12: =G12-M12 -> 971.73 | O12: =IFERROR(G12/F12,0) -> 0.32305801
A13: 46242 | B13: 1739 | C13: 3490 | D13: 0 | E13: 0 | F13: =B13+C13+D13+E13 -> 5229 | G13: 1758.96 | H13: 75.67 | I13: 292.89 | J13: 0 | K13: 564.46 | L13: 0 | M13: =SUM(H13:L13) -> 933.02 | N13: =G13-M13 -> 825.94 | O13: =IFERROR(G13/F13,0) -> 0.33638554
A14: 46243 | B14: 1458 | C14: 2228 | D14: 0 | E14: 0 | F14: =B14+C14+D14+E14 -> 3686 | G14: 1224.98 | H14: 75.67 | I14: 292.89 | J14: 0 | K14: 564.46 | L14: 0 | M14: =SUM(H14:L14) -> 933.02 | N14: =G14-M14 -> 291.96 | O14: =IFERROR(G14/F14,0) -> 0.33233315
A15: 46244 | B15: 1675 | C15: 3130 | D15: 0 | E15: 0 | F15: =B15+C15+D15+E15 -> 4805 | G15: 1650.07 | H15: 75.67 | I15: 292.89 | J15: 0 | K15: 564.46 | L15: 0 | M15: =SUM(H15:L15) -> 933.02 | N15: =G15-M15 -> 717.05 | O15: =IFERROR(G15/F15,0) -> 0.34340687
A16: 46245 | B16: 1380 | C16: 3155 | D16: 0 | E16: 0 | F16: =B16+C16+D16+E16 -> 4535 | G16: 1634.94 | H16: 75.67 | I16: 292.89 | J16: 0 | K16: 564.46 | L16: 0 | M16: =SUM(H16:L16) -> 933.02 | N16: =G16-M16 -> 701.92 | O16: =IFERROR(G16/F16,0) -> 0.36051599
A17: 46246 | B17: 1182 | C17: 3031 | D17: 0 | E17: 0 | F17: =B17+C17+D17+E17 -> 4213 | G17: 1449.01 | H17: 75.67 | I17: 292.89 | J17: 0 | K17: 564.46 | L17: 0 | M17: =SUM(H17:L17) -> 933.02 | N17: =G17-M17 -> 515.99 | O17: =IFERROR(G17/F17,0) -> 0.34393781
A18: 46247 | B18: 1520 | C18: 2764 | D18: 0 | E18: 0 | F18: =B18+C18+D18+E18 -> 4284 | G18: 1326.82 | H18: 75.67 | I18: 292.89 | J18: 0 | K18: 564.46 | L18: 0 | M18: =SUM(H18:L18) -> 933.02 | N18: =G18-M18 -> 393.8 | O18: =IFERROR(G18/F18,0) -> 0.30971522
A19: 46248 | B19: 1862 | C19: 4651 | D19: 0 | E19: 0 | F19: =B19+C19+D19+E19 -> 6513 | G19: 2036.42 | H19: 75.67 | I19: 292.89 | J19: 0 | K19: 564.46 | L19: 0 | M19: =SUM(H19:L19) -> 933.02 | N19: =G19-M19 -> 1103.4 | O19: =IFERROR(G19/F19,0) -> 0.31267004
A20: 46249 | B20: 1360 | C20: 3792 | D20: 0 | E20: 0 | F20: =B20+C20+D20+E20 -> 5152 | G20: 1954.57 | H20: 75.67 | I20: 292.89 | J20: 0 | K20: 564.46 | L20: 0 | M20: =SUM(H20:L20) -> 933.02 | N20: =G20-M20 -> 1021.55 | O20: =IFERROR(G20/F20,0) -> 0.37938082
A21: 46250 | B21: 922 | C21: 2523 | D21: 0 | E21: 0 | F21: =B21+C21+D21+E21 -> 3445 | G21: 1262.84 | H21: 75.67 | I21: 292.89 | J21: 0 | K21: 564.46 | L21: 0 | M21: =SUM(H21:L21) -> 933.02 | N21: =G21-M21 -> 329.82 | O21: =IFERROR(G21/F21,0) -> 0.36657184
A22: 46251 | B22: 1389 | C22: 2868 | D22: 0 | E22: 0 | F22: =B22+C22+D22+E22 -> 4257 | G22: 1370.22 | H22: 75.67 | I22: 292.89 | J22: 0 | K22: 564.46 | L22: 0 | M22: =SUM(H22:L22) -> 933.02 | N22: =G22-M22 -> 437.2 | O22: =IFERROR(G22/F22,0) -> 0.32187456
A23: 46252 | B23: 1368 | C23: 3406 | D23: 0 | E23: 0 | F23: =B23+C23+D23+E23 -> 4774 | G23: 1642.74 | H23: 75.67 | I23: 292.89 | J23: 0 | K23: 564.46 | L23: 0 | M23: =SUM(H23:L23) -> 933.02 | N23: =G23-M23 -> 709.72 | O23: =IFERROR(G23/F23,0) -> 0.34410138
... A36: 46265 | B36: 1399 | C36: 2553 | D36: 0 | E36: 0 | F36: =B36+C36+D36+E36 -> 3952 | G36: 1391.05 | H36: 75.67 | I36: 292.89 | J36: 0 | K36: 564.46 | L36: 0 | M36: =SUM(H36:L36) -> 933.02 | N36: =G36-M36 -> 458.03 | O36: =IFERROR(G36/F36,0) -> 0.35198634
A38: TOTAL | B38: =SUM(B6:B36) -> 43411 | C38: =SUM(C6:C36) -> 87588 | D38: =SUM(D6:D36) -> -297 | E38: =SUM(E6:E36) -> 1448 | F38: =SUM(F6:F36) -> 132150 | G38: =SUM(G6:G36) -> 44816.26 | H38: =SUM(H6:H36) -> 2345.77 | I38: =SUM(I6:I36) -> 9079.59 | ... N38: =SUM(N6:N36) -> 16382.1 | O38: =IFERROR(G38/F38,0) -> 0.33913174

Sheet September 2026
A1: September 2026 — Daily Sales & P&L
A2: Sample data for this demo. Yellow cells are editable — swap in your own shop's numbers to reuse this template.
A4: Date | B4: Cash Sales | C4: GPay Sales | D4: Sales Return | E4: Credit Redeemed | F4: Total Sales | G4: Gross Profit | H4: Electric Bill | I4: Shop Rent | J4: Shop Expense | K4: Salary | L4: Donation | M4: Total Expense | N4: Net P&L | O4: Margin % | P4: Notes
A6: 46266 | B6: 1262 | C6: 2700 | D6: 0 | E6: 0 | F6: =B6+C6+D6+E6 -> 3962 | G6: 1284.36 | H6: 92.32 | I6: 319.94 | J6: 0 | K6: 638.06 | L6: 0 | M6: =SUM(H6:L6) -> 1050.32 | N6: =G6-M6 -> 234.04 | O6: =IFERROR(G6/F6,0) -> 0.32416961
A7: 46267 | B7: 961 | C7: 2653 | D7: 0 | E7: 0 | F7: =B7+C7+D7+E7 -> 3614 | G7: 1194.46 | H7: 92.32 | I7: 319.94 | J7: 0 | K7: 638.06 | L7: 0 | M7: =SUM(H7:L7) -> 1050.32 | N7: =G7-M7 -> 144.14 | O7: =IFERROR(G7/F7,0) -> 0.33050913
A8: 46268 | B8: 1251 | C8: 2273 | D8: 0 | E8: 0 | F8: =B8+C8+D8+E8 -> 3524 | G8: 1063.39 | H8: 92.32 | I8: 319.94 | J8: 0 | K8: 638.06 | L8: 0 | M8: =SUM(H8:L8) -> 1050.32 | N8: =G8-M8 -> 13.07 | O8: =IFERROR(G8/F8,0) -> 0.30175653
A9: 46269 | B9: 868 | C9: 2587 | D9: 0 | E9: 0 | F9: =B9+C9+D9+E9 -> 3455 | G9: 1275.6 | H9: 92.32 | I9: 319.94 | J9: 0 | K9: 638.06 | L9: 0 | M9: =SUM(H9:L9) -> 1050.32 | N9: =G9-M9 -> 225.28 | O9: =IFERROR(G9/F9,0) -> 0.36920405
A10: 46270 | B10: 1391 | C10: 2206 | D10: 0 | E10: 0 | F10: =B10+C10+D10+E10 -> 3597 | G10: 1293.53 | H10: 92.32 | I10: 319.94 | J10: 0 | K10: 638.06 | L10: 0 | M10: =SUM(H10:L10) -> 1050.32 | N10: =G10-M10 -> 243.21 | O10: =IFERROR(G10/F10,0) -> 0.35961357
A11: 46271 | B11: 896 | C11: 1550 | D11: 0 | E11: 0 | F11: =B11+C11+D11+E11 -> 2446 | G11: 778.83 | H11: 92.32 | I11: 319.94 | J11: 0 | K11: 638.06 | L11: 0 | M11: =SUM(H11:L11) -> 1050.32 | N11: =G11-M11 -> -271.49 | O11: =IFERROR(G11/F11,0) -> 0.31840965
A12: 46272 | B12: 681 | C12: 1764 | D12: 0 | E12: 0 | F12: =B12+C12+D12+E12 -> 2445 | G12: 782.52 | H12: 92.32 | I12: 319.94 | J12: 0 | K12: 638.06 | L12: 0 | M12: =SUM(H12:L12) -> 1050.32 | N12: =G12-M12 -> -267.8 | O12: =IFERROR(G12/F12,0) -> 0.32004908
A13: 46273 | B13: 1027 | C13: 1890 | D13: 0 | E13: 0 | F13: =B13+C13+D13+E13 -> 2917 | G13: 907.02 | H13: 92.32 | I13: 319.94 | J13: 94 | K13: 638.06 | L13: 79 | M13: =SUM(H13:L13) -> 1223.32 | N13: =G13-M13 -> -316.3 | O13: =IFERROR(G13/F13,0) -> 0.31094275
A14: 46274 | B14: 634 | C14: 1854 | D14: 0 | E14: 0 | F14: =B14+C14+D14+E14 -> 2488 | G14: 819.02 | H14: 92.32 | I14: 319.94 | J14: 136 | K14: 638.06 | L14: 0 | M14: =SUM(H14:L14) -> 1186.32 | N14: =G14-M14 -> -367.3 | O14: =IFERROR(G14/F14,0) -> 0.3291881
A15: 46275 | B15: 928 | C15: 2043 | D15: 0 | E15: 0 | F15: =B15+C15+D15+E15 -> 2971 | G15: 939.02 | H15: 92.32 | I15: 319.94 | J15: 0 | K15: 638.06 | L15: 0 | M15: =SUM(H15:L15) -> 1050.32 | N15: =G15-M15 -> -111.3 | O15: =IFERROR(G15/F15,0) -> 0.31606193
A16: 46276 | B16: 1270 | C16: 2897 | D16: 0 | E16: 0 | F16: =B16+C16+D16+E16 -> 4167 | G16: 1417.38 | H16: 92.32 | I16: 319.94 | J16: 0 | K16: 638.06 | L16: 0 | M16: =SUM(H16:L16) -> 1050.32 | N16: =G16-M16 -> 367.06 | O16: =IFERROR(G16/F16,0) -> 0.34014399
A17: 46277 | B17: 1457 | C17: 2308 | D17: -2466 | E17: 0 | F17: =B17+C17+D17+E17 -> 1299 | G17: 490.23 | H17: 92.32 | I17: 319.94 | J17: 0 | K17: 638.06 | L17: 0 | M17: =SUM(H17:L17) -> 1050.32 | N17: =G17-M17 -> -560.09 | O17: =IFERROR(G17/F17,0) -> 0.3773903
A18: 46278 | B18: 963 | C18: 1636 | D18: 0 | E18: 0 | F18: =B18+C18+D18+E18 -> 2599 | G18: 877.08 | H18: 92.32 | I18: 319.94 | J18: 113 | K18: 638.06 | L18: 0 | M18: =SUM(H18:L18) -> 1163.32 | N18: =G18-M18 -> -286.24 | O18: =IFERROR(G18/F18,0) -> 0.33746826
A19: 46279 | B19: 0 | C19: 0 | D19: 0 | E19: 0 | F19: =B19+C19+D19+E19 -> 0 | G19: 0 | H19: 92.32 | I19: 319.94 | J19: 0 | K19: 0 | L19: 0 | M19: =SUM(H19:L19) -> 412.26 | N19: =G19-M19 -> -412.26 | O19: =IFERROR(G19/F19,0) -> 0 | P19: Shop closed
A20: 46280 | B20: 1012 | C20: 1674 | D20: 0 | E20: 0 | F20: =B20+C20+D20+E20 -> 2686 | G20: 925.56 | H20: 92.32 | I20: 319.94 | J20: 59 | K20: 638.06 | L20: 0 | M20: =SUM(H20:L20) -> 1109.32 | N20: =G20-M20 -> -183.76 | O20: =IFERROR(G20/F20,0) -> 0.34458675
A21: 46281 | B21: 719 | C21: 1959 | D21: 0 | E21: 0 | F21: =B21+C21+D21+E21 -> 2678 | G21: 882.37 | H21: 92.32 | I21: 319.94 | J21: 0 | K21: 638.06 | L21: 0 | M21: =SUM(H21:L21) -> 1050.32 | N21: =G21-M21 -> -167.95 | O21: =IFERROR(G21/F21,0) -> 0.32948842
A22: 46282 | B22: 1036 | C22: 2337 | D22: 0 | E22: 0 | F22: =B22+C22+D22+E22 -> 3373 | G22: 1184.21 | H22: 92.32 | I22: 319.94 | J22: 0 | K22: 638.06 | L22: 0 | M22: =SUM(H22:L22) -> 1050.32 | N22: =G22-M22 -> 133.89 | O22: =IFERROR(G22/F22,0) -> 0.35108509
A23: 46283 | B23: 1303 | C23: 2760 | D23: 0 | E23: 0 | F23: =B23+C23+D23+E23 -> 4063 | G23: 1420.28 | H23: 92.32 | I23: 319.94 | J23: 0 | K23: 638.06 | L23: 0 | M23: =SUM(H23:L23) -> 1050.32 | N23: =G23-M23 -> 369.96 | O23: =IFERROR(G23/F23,0) -> 0.34956436
A24: 46284 | B24: 1609 | C24: 3103 | D24: 0 | E24: 0 | F24: =B24+C24+D24+E24 -> 4712 | G24: 1657.74 | H24: 92.32 | I24: 319.94 | J24: 0 | K24: 638.06 | L24: 0 | M24: =SUM(H24:L24) -> 1050.32 | N24: =G24-M24 -> 607.42 | O24: =IFERROR(G24/F24,0) -> 0.35181239
A25: 46285 | B25: 964 | C25: 1751 | D25: 0 | E25: 0 | F25: =B25+C25+D25+E25 -> 2715 | G25: 955.51 | H25: 92.32 | I25: 319.94 | J25: 7 | K25: 638.06 | L25: 100 | M25: =SUM(H25:L25) -> 1157.32 | N25: =G25-M25 -> -201.81 | O25: =IFERROR(G25/F25,0) -> 0.35193738
A26: 46286 | B26: 891 | C26: 2440 | D26: 0 | E26: 772 | F26: =B26+C26+D26+E26 -> 4103 | G26: 1407.34 | H26: 92.32 | I26: 319.94 | J26: 0 | K26: 638.06 | L26: 0 | M26: =SUM(H26:L26) -> 1050.32 | N26: =G26-M26 -> 357.02 | O26: =IFERROR(G26/F26,0) -> 0.34300268
A27: 46287 | B27: 1087 | C27: 1683 | D27: 0 | E27: 0 | F27: =B27+C27+D27+E27 -> 2770 | G27: 985.34 | H27: 92.32 | I27: 319.94 | J27: 0 | K27: 638.06 | L27: 0 | M27: =SUM(H27:L27) -> 1050.32 | N27: =G27-M27 -> -64.98 | O27: =IFERROR(G27/F27,0) -> 0.35571841
A28: 46288 | B28: 1227 | C28: 2191 | D28: 0 | E28: 0 | F28: =B28+C28+D28+E28 -> 3418 | G28: 1267.51 | H28: 92.32 | I28: 319.94 | J28: 0 | K28: 638.06 | L28: 0 | M28: =SUM(H28:L28) -> 1050.32 | N28: =G28-M28 -> 217.19 | O28: =IFERROR(G28/F28,0) -> 0.37083382
A29: 46289 | B29: 1073 | C29: 2060 | D29: 0 | E29: 0 | F29: =B29+C29+D29+E29 -> 3133 | G29: 1175.26 | H29: 92.32 | I29: 319.94 | J29: 0 | K29: 638.06 | L29: 0 | M29: =SUM(H29:L29) -> 1050.32 | N29: =G29-M29 -> 124.94 | O29: =IFERROR(G29/F29,0) -> 0.37512289
A30: 46290 | B30: 1322 | C30: 3355 | D30: 0 | E30: 0 | F30: =B30+C30+D30+E30 -> 4677 | G30: 1569.49 | H30: 92.32 | I30: 319.94 | J30: 0 | K30: 638.06 | L30: 0 | M30: =SUM(H30:L30) -> 1050.32 | N30: =G30-M30 -> 519.17 | O30: =IFERROR(G30/F30,0) -> 0.33557622
A31: 46291 | B31: 2056 | C31: 3122 | D31: 0 | E31: 0 | F31: =B31+C31+D31+E31 -> 5178 | G31: 1705.56 | H31: 92.32 | I31: 319.94 | J31: 0 | K31: 638.06 | L31: 0 | M31: =SUM(H31:L31) -> 1050.32 | N31: =G31-M31 -> 655.24 | O31: =IFERROR(G31/F31,0) -> 0.32938586
... A35: 46295 | B35: 926 | C35: 1590 | D35: 0 | E35: 0 | F35: =B35+C35+D35+E35 -> 2516 | G35: 796.1 | H35: 92.32 | I35: 319.94 | J35: 0 | K35: 638.06 | L35: 0 | M35: =SUM(H35:L35) -> 1050.32 | N35: =G35-M35 -> -254.22 | O35: =IFERROR(G35/F35,0) -> 0.31641494
A38: TOTAL | B38: =SUM(B6:B36) -> 31869 | C38: =SUM(C6:C36) -> 64132 | D38: =SUM(D6:D36) -> -2466 | E38: =SUM(E6:E36) -> 772 | F38: =SUM(F6:F36) -> 94307 | G38: =SUM(G6:G36) -> 31788.16 | H38: =SUM(H6:H36) -> 2769.6 | I38: =SUM(I6:I36) -> 9598.2 | ... N38: =SUM(N6:N36) -> 328.62 | O38: =IFERROR(G38/F38,0) -> 0.33707106

Sheet October 2026
A1: October 2026 — Daily Sales & P&L
A2: Sample data for this demo. Yellow cells are editable — swap in your own shop's numbers to reuse this template.
A4: Date | B4: Cash Sales | C4: GPay Sales | D4: Sales Return | E4: Credit Redeemed | F4: Total Sales | G4: Gross Profit | H4: Electric Bill | I4: Shop Rent | J4: Shop Expense | K4: Salary | L4: Donation | M4: Total Expense | N4: Net P&L | O4: Margin % | P4: Notes
A6: 46296 | B6: 942 | C6: 1418 | D6: 0 | E6: 0 | F6: =B6+C6+D6+E6 -> 2360 | G6: 808.17 | H6: 78.67 | I6: 331.17 | J6: 0 | K6: 565.04 | L6: 0 | M6: =SUM(H6:L6) -> 974.88 | N6: =G6-M6 -> -166.71 | O6: =IFERROR(G6/F6,0) -> 0.34244492
A7: 46297 | B7: 1276 | C7: 3541 | D7: 0 | E7: 0 | F7: =B7+C7+D7+E7 -> 4817 | G7: 1715.54 | H7: 78.67 | I7: 331.17 | J7: 0 | K7: 565.04 | L7: 0 | M7: =SUM(H7:L7) -> 974.88 | N7: =G7-M7 -> 740.66 | O7: =IFERROR(G7/F7,0) -> 0.35614283
A8: 46298 | B8: 1336 | C8: 2320 | D8: 0 | E8: 0 | F8: =B8+C8+D8+E8 -> 3656 | G8: 1307.63 | H8: 78.67 | I8: 331.17 | J8: 0 | K8: 565.04 | L8: 0 | M8: =SUM(H8:L8) -> 974.88 | N8: =G8-M8 -> 332.75 | O8: =IFERROR(G8/F8,0) -> 0.35766685
A9: 46299 | B9: 687 | C9: 1728 | D9: 0 | E9: 0 | F9: =B9+C9+D9+E9 -> 2415 | G9: 789.98 | H9: 78.67 | I9: 331.17 | J9: 0 | K9: 565.04 | L9: 0 | M9: =SUM(H9:L9) -> 974.88 | N9: =G9-M9 -> -184.9 | O9: =IFERROR(G9/F9,0) -> 0.32711387
A10: 46300 | B10: 0 | C10: 0 | D10: 0 | E10: 0 | F10: =B10+C10+D10+E10 -> 0 | G10: 0 | H10: 78.67 | I10: 331.17 | J10: 0 | K10: 0 | L10: 0 | M10: =SUM(H10:L10) -> 409.84 | N10: =G10-M10 -> -409.84 | O10: =IFERROR(G10/F10,0) -> 0 | P10: Shop closed
A11: 46301 | B11: 741 | C11: 1678 | D11: 0 | E11: 0 | F11: =B11+C11+D11+E11 -> 2419 | G11: 755.24 | H11: 78.67 | I11: 331.17 | J11: 0 | K11: 565.04 | L11: 83 | M11: =SUM(H11:L11) -> 1057.88 | N11: =G11-M11 -> -302.64 | O11: =IFERROR(G11/F11,0) -> 0.31221166
A12: 46302 | B12: 922 | C12: 2571 | D12: 0 | E12: 0 | F12: =B12+C12+D12+E12 -> 3493 | G12: 1074.88 | H12: 78.67 | I12: 331.17 | J12: 0 | K12: 565.04 | L12: 0 | M12: =SUM(H12:L12) -> 974.88 | N12: =G12-M12 -> 100 | O12: =IFERROR(G12/F12,0) -> 0.30772402
A13: 46303 | B13: 1053 | C13: 2104 | D13: 0 | E13: 0 | F13: =B13+C13+D13+E13 -> 3157 | G13: 1095.22 | H13: 78.67 | I13: 331.17 | J13: 0 | K13: 565.04 | L13: 0 | M13: =SUM(H13:L13) -> 974.88 | N13: =G13-M13 -> 120.34 | O13: =IFERROR(G13/F13,0) -> 0.34691796
A14: 46304 | B14: 1268 | C14: 3456 | D14: 0 | E14: 0 | F14: =B14+C14+D14+E14 -> 4724 | G14: 1550.83 | H14: 78.67 | I14: 331.17 | J14: 0 | K14: 565.04 | L14: 0 | M14: =SUM(H14:L14) -> 974.88 | N14: =G14-M14 -> 575.95 | O14: =IFERROR(G14/F14,0) -> 0.32828747
A15: 46305 | B15: 1581 | C15: 2576 | D15: -1931 | E15: 0 | F15: =B15+C15+D15+E15 -> 2226 | G15: 840.25 | H15: 78.67 | I15: 331.17 | J15: 0 | K15: 565.04 | L15: 0 | M15: =SUM(H15:L15) -> 974.88 | N15: =G15-M15 -> -134.63 | O15: =IFERROR(G15/F15,0) -> 0.3774708
A16: 46306 | B16: 1016 | C16: 2001 | D16: 0 | E16: 0 | F16: =B16+C16+D16+E16 -> 3017 | G16: 956.45 | H16: 78.67 | I16: 331.17 | J16: 0 | K16: 565.04 | L16: 0 | M16: =SUM(H16:L16) -> 974.88 | N16: =G16-M16 -> -18.43 | O16: =IFERROR(G16/F16,0) -> 0.31702022
A17: 46307 | B17: 835 | C17: 2302 | D17: 0 | E17: 0 | F17: =B17+C17+D17+E17 -> 3137 | G17: 1153.25 | H17: 78.67 | I17: 331.17 | J17: 0 | K17: 565.04 | L17: 0 | M17: =SUM(H17:L17) -> 974.88 | N17: =G17-M17 -> 178.37 | O17: =IFERROR(G17/F17,0) -> 0.36762831
A18: 46308 | B18: 843 | C18: 1664 | D18: 0 | E18: 0 | F18: =B18+C18+D18+E18 -> 2507 | G18: 914 | H18: 78.67 | I18: 331.17 | J18: 0 | K18: 565.04 | L18: 0 | M18: =SUM(H18:L18) -> 974.88 | N18: =G18-M18 -> -60.88 | O18: =IFERROR(G18/F18,0) -> 0.36457918
A19: 46309 | B19: 1164 | C19: 1958 | D19: 0 | E19: 0 | F19: =B19+C19+D19+E19 -> 3122 | G19: 1089.85 | H19: 78.67 | I19: 331.17 | J19: 0 | K19: 565.04 | L19: 93 | M19: =SUM(H19:L19) -> 1067.88 | N19: =G19-M19 -> 21.97 | O19: =IFERROR(G19/F19,0) -> 0.34908712
A20: 46310 | B20: 1427 | C20: 2383 | D20: 0 | E20: 0 | F20: =B20+C20+D20+E20 -> 3810 | G20: 1224.52 | H20: 78.67 | I20: 331.17 | J20: 0 | K20: 565.04 | L20: 0 | M20: =SUM(H20:L20) -> 974.88 | N20: =G20-M20 -> 249.64 | O20: =IFERROR(G20/F20,0) -> 0.32139633
A21: 46311 | B21: 962 | C21: 2284 | D21: 0 | E21: 0 | F21: =B21+C21+D21+E21 -> 3246 | G21: 1062.05 | H21: 78.67 | I21: 331.17 | J21: 130 | K21: 565.04 | L21: 0 | M21: =SUM(H21:L21) -> 1104.88 | N21: =G21-M21 -> -42.83 | O21: =IFERROR(G21/F21,0) -> 0.32718731
A22: 46312 | B22: 1489 | C22: 3314 | D22: 0 | E22: 0 | F22: =B22+C22+D22+E22 -> 4803 | G22: 1495.41 | H22: 78.67 | I22: 331.17 | J22: 0 | K22: 565.04 | L22: 75 | M22: =SUM(H22:L22) -> 1049.88 | N22: =G22-M22 -> 445.53 | O22: =IFERROR(G22/F22,0) -> 0.31134916
... A36: 46326 | B36: 867 | C36: 2426 | D36: 0 | E36: 0 | F36: =B36+C36+D36+E36 -> 3293 | G36: 1210.37 | H36: 78.67 | I36: 331.17 | J36: 0 | K36: 565.04 | L36: 0 | M36: =SUM(H36:L36) -> 974.88 | N36: =G36-M36 -> 235.49 | O36: =IFERROR(G36/F36,0) -> 0.36755846
A38: TOTAL | B38: =SUM(B6:B36) -> 32377 | C38: =SUM(C6:C36) -> 68626 | D38: =SUM(D6:D36) -> -1931 | E38: =SUM(E6:E36) -> 2151 | F38: =SUM(F6:F36) -> 101223 | G38: =SUM(G6:G36) -> 34165.3 | H38: =SUM(H6:H36) -> 2438.77 | I38: =SUM(I6:I36) -> 10266.27 | ... N38: =SUM(N6:N36) -> 3879.06 | O38: =IFERROR(G38/F38,0) -> 0.33752507

Sheet November 2026
A1: November 2026 — Daily Sales & P&L
A2: Sample data for this demo. Yellow cells are editable — swap in your own shop's numbers to reuse this template.
A4: Date | B4: Cash Sales | C4: GPay Sales | D4: Sales Return | E4: Credit Redeemed | F4: Total Sales | G4: Gross Profit | H4: Electric Bill | I4: Shop Rent | J4: Shop Expense | K4: Salary | L4: Donation | M4: Total Expense | N4: Net P&L | O4: Margin % | P4: Notes
A6: 46327 | B6: 1251 | C6: 2357 | D6: 0 | E6: 0 | F6: =B6+C6+D6+E6 -> 3608 | G6: 1364.51 | H6: 76.5 | I6: 302.51 | J6: 89 | K6: 557.42 | L6: 0 | M6: =SUM(H6:L6) -> 1025.43 | N6: =G6-M6 -> 339.08 | O6: =IFERROR(G6/F6,0) -> 0.37819013
A7: 46328 | B7: 1163 | C7: 2289 | D7: 0 | E7: 0 | F7: =B7+C7+D7+E7 -> 3452 | G7: 1299.12 | H7: 76.5 | I7: 302.51 | J7: 0 | K7: 557.42 | L7: 91 | M7: =SUM(H7:L7) -> 1027.43 | N7: =G7-M7 -> 271.69 | O7: =IFERROR(G7/F7,0) -> 0.37633835
A8: 46329 | B8: 1539 | C8: 3046 | D8: 0 | E8: 0 | F8: =B8+C8+D8+E8 -> 4585 | G8: 1444.55 | H8: 76.5 | I8: 302.51 | J8: 0 | K8: 557.42 | L8: 0 | M8: =SUM(H8:L8) -> 936.43 | N8: =G8-M8 -> 508.12 | O8: =IFERROR(G8/F8,0) -> 0.31505998
A9: 46330 | B9: 1575 | C9: 2426 | D9: 0 | E9: 0 | F9: =B9+C9+D9+E9 -> 4001 | G9: 1344.5 | H9: 76.5 | I9: 302.51 | J9: 0 | K9: 557.42 | L9: 0 | M9: =SUM(H9:L9) -> 936.43 | N9: =G9-M9 -> 408.07 | O9: =IFERROR(G9/F9,0) -> 0.33604099
A10: 46331 | B10: 1221 | C10: 1852 | D10: 0 | E10: 0 | F10: =B10+C10+D10+E10 -> 3073 | G10: 942.63 | H10: 76.5 | I10: 302.51 | J10: 0 | K10: 557.42 | L10: 71 | M10: =SUM(H10:L10) -> 1007.43 | N10: =G10-M10 -> -64.8 | O10: =IFERROR(G10/F10,0) -> 0.30674585
A11: 46332 | B11: 1609 | C11: 2427 | D11: 0 | E11: 0 | F11: =B11+C11+D11+E11 -> 4036 | G11: 1380.01 | H11: 76.5 | I11: 302.51 | J11: 0 | K11: 557.42 | L11: 0 | M11: =SUM(H11:L11) -> 936.43 | N11: =G11-M11 -> 443.58 | O11: =IFERROR(G11/F11,0) -> 0.34192517
A12: 46333 | B12: 1714 | C12: 2707 | D12: 0 | E12: 0 | F12: =B12+C12+D12+E12 -> 4421 | G12: 1463.32 | H12: 76.5 | I12: 302.51 | J12: 0 | K12: 557.42 | L12: 0 | M12: =SUM(H12:L12) -> 936.43 | N12: =G12-M12 -> 526.89 | O12: =IFERROR(G12/F12,0) -> 0.33099299
A13: 46334 | B13: 684 | C13: 1969 | D13: 0 | E13: 0 | F13: =B13+C13+D13+E13 -> 2653 | G13: 929.8 | H13: 76.5 | I13: 302.51 | J13: 0 | K13: 557.42 | L13: 0 | M13: =SUM(H13:L13) -> 936.43 | N13: =G13-M13 -> -6.63 | O13: =IFERROR(G13/F13,0) -> 0.35047116
A14: 46335 | B14: 1029 | C14: 2054 | D14: 0 | E14: 0 | F14: =B14+C14+D14+E14 -> 3083 | G14: 1020.24 | H14: 76.5 | I14: 302.51 | J14: 0 | K14: 557.42 | L14: 0 | M14: =SUM(H14:L14) -> 936.43 | N14: =G14-M14 -> 83.81 | O14: =IFERROR(G14/F14,0) -> 0.33092442
A15: 46336 | B15: 1663 | C15: 2550 | D15: 0 | E15: 0 | F15: =B15+C15+D15+E15 -> 4213 | G15: 1467.03 | H15: 76.5 | I15: 302.51 | J15: 0 | K15: 557.42 | L15: 0 | M15: =SUM(H15:L15) -> 936.43 | N15: =G15-M15 -> 530.6 | O15: =IFERROR(G15/F15,0) -> 0.34821505
A16: 46337 | B16: 1027 | C16: 1911 | D16: 0 | E16: 0 | F16: =B16+C16+D16+E16 -> 2938 | G16: 1096.87 | H16: 76.5 | I16: 302.51 | J16: 0 | K16: 557.42 | L16: 0 | M16: =SUM(H16:L16) -> 936.43 | N16: =G16-M16 -> 160.44 | O16: =IFERROR(G16/F16,0) -> 0.37333901
A17: 46338 | B17: 1597 | C17: 2975 | D17: 0 | E17: 0 | F17: =B17+C17+D17+E17 -> 4572 | G17: 1418.77 | H17: 76.5 | I17: 302.51 | J17: 0 | K17: 557.42 | L17: 0 | M17: =SUM(H17:L17) -> 936.43 | N17: =G17-M17 -> 482.34 | O17: =IFERROR(G17/F17,0) -> 0.31031715
... A33: 46354 | B33: 1878 | C33: 3388 | D33: 0 | E33: 0 | F33: =B33+C33+D33+E33 -> 5266 | G33: 1797.14 | H33: 76.5 | I33: 302.51 | J33: 13 | K33: 557.42 | L33: 0 | M33: =SUM(H33:L33) -> 949.43 | N33: =G33-M33 -> 847.71 | O33: =IFERROR(G33/F33,0) -> 0.34127231
A34: 46355 | B34: 0 | C34: 0 | D34: 0 | E34: 0 | F34: =B34+C34+D34+E34 -> 0 | G34: 0 | H34: 76.5 | I34: 302.51 | J34: 0 | K34: 0 | L34: 0 | M34: =SUM(H34:L34) -> 379.01 | N34: =G34-M34 -> -379.01 | O34: =IFERROR(G34/F34,0) -> 0 | P34: Shop closed
A35: 46356 | B35: 774 | C35: 2162 | D35: 0 | E35: 0 | F35: =B35+C35+D35+E35 -> 2936 | G35: 1094.66 | H35: 76.5 | I35: 302.51 | J35: 0 | K35: 557.42 | L35: 0 | M35: =SUM(H35:L35) -> 936.43 | N35: =G35-M35 -> 158.23 | O35: =IFERROR(G35/F35,0) -> 0.3728406
A38: TOTAL | B38: =SUM(B6:B36) -> 39106 | C38: =SUM(C6:C36) -> 78895 | D38: =SUM(D6:D36) -> -1809 | E38: =SUM(E6:E36) -> 2180 | F38: =SUM(F6:F36) -> 118372 | G38: =SUM(G6:G36) -> 40816.18 | H38: =SUM(H6:H36) -> 2295 | I38: =SUM(I6:I36) -> 9075.3 | ... N38: =SUM(N6:N36) -> 12970.7 | O38: =IFERROR(G38/F38,0) -> 0.34481279

Sheet December 2026
A1: December 2026 — Daily Sales & P&L
A2: Sample data for this demo. Yellow cells are editable — swap in your own shop's numbers to reuse this template.
A4: Date | B4: Cash Sales | C4: GPay Sales | D4: Sales Return | E4: Credit Redeemed | F4: Total Sales | G4: Gross Profit | H4: Electric Bill | I4: Shop Rent | J4: Shop Expense | K4: Salary | L4: Donation | M4: Total Expense | N4: Net P&L | O4: Margin % | P4: Notes
A6: 46357 | B6: 1183 | C6: 2723 | D6: 0 | E6: 0 | F6: =B6+C6+D6+E6 -> 3906 | G6: 1350.12 | H6: 72.03 | I6: 336.68 | J6: 0 | K6: 500.31 | L6: 0 | M6: =SUM(H6:L6) -> 909.02 | N6: =G6-M6 -> 441.1 | O6: =IFERROR(G6/F6,0) -> 0.34565284
A7: 46358 | B7: 1353 | C7: 2766 | D7: 0 | E7: 0 | F7: =B7+C7+D7+E7 -> 4119 | G7: 1354.53 | H7: 72.03 | I7: 336.68 | J7: 0 | K7: 500.31 | L7: 0 | M7: =SUM(H7:L7) -> 909.02 | N7: =G7-M7 -> 445.51 | O7: =IFERROR(G7/F7,0) -> 0.32884924
A8: 46359 | B8: 1332 | C8: 2289 | D8: 0 | E8: 0 | F8: =B8+C8+D8+E8 -> 3621 | G8: 1233.35 | H8: 72.03 | I8: 336.68 | J8: 131 | K8: 500.31 | L8: 39 | M8: =SUM(H8:L8) -> 1079.02 | N8: =G8-M8 -> 154.33 | O8: =IFERROR(G8/F8,0) -> 0.34061033
A9: 46360 | B9: 2072 | C9: 4699 | D9: 0 | E9: 0 | F9: =B9+C9+D9+E9 -> 6771 | G9: 2436.11 | H9: 72.03 | I9: 336.68 | J9: 0 | K9: 500.31 | L9: 24 | M9: =SUM(H9:L9) -> 933.02 | N9: =G9-M9 -> 1503.09 | O9: =IFERROR(G9/F9,0) -> 0.35978585
A10: 46361 | B10: 1956 | C10: 3655 | D10: 0 | E10: 0 | F10: =B10+C10+D10+E10 -> 5611 | G10: 1729.83 | H10: 72.03 | I10: 336.68 | J10: 0 | K10: 500.31 | L10: 0 | M10: =SUM(H10:L10) -> 909.02 | N10: =G10-M10 -> 820.81 | O10: =IFERROR(G10/F10,0) -> 0.30829264
A11: 46362 | B11: 856 | C11: 2313 | D11: 0 | E11: 0 | F11: =B11+C11+D11+E11 -> 3169 | G11: 1040.01 | H11: 72.03 | I11: 336.68 | J11: 0 | K11: 500.31 | L11: 0 | M11: =SUM(H11:L11) -> 909.02 | N11: =G11-M11 -> 130.99 | O11: =IFERROR(G11/F11,0) -> 0.32818239
A12: 46363 | B12: 1305 | C12: 2179 | D12: 0 | E12: 0 | F12: =B12+C12+D12+E12 -> 3484 | G12: 1236.03 | H12: 72.03 | I12: 336.68 | J12: 0 | K12: 500.31 | L12: 0 | M12: =SUM(H12:L12) -> 909.02 | N12: =G12-M12 -> 327.01 | O12: =IFERROR(G12/F12,0) -> 0.35477325
A13: 46364 | B13: 1518 | C13: 3957 | D13: 0 | E13: 507 | F13: =B13+C13+D13+E13 -> 5982 | G13: 2137.27 | H13: 72.03 | I13: 336.68 | J13: 0 | K13: 500.31 | L13: 20 | M13: =SUM(H13:L13) -> 929.02 | N13: =G13-M13 -> 1208.25 | O13: =IFERROR(G13/F13,0) -> 0.35728352
A14: 46365 | B14: 1647 | C14: 2820 | D14: 0 | E14: 0 | F14: =B14+C14+D14+E14 -> 4467 | G14: 1656.65 | H14: 72.03 | I14: 336.68 | J14: 0 | K14: 500.31 | L14: 0 | M14: =SUM(H14:L14) -> 909.02 | N14: =G14-M14 -> 747.63 | O14: =IFERROR(G14/F14,0) -> 0.37086411
A15: 46366 | B15: 1635 | C15: 3644 | D15: 0 | E15: 0 | F15: =B15+C15+D15+E15 -> 5279 | G15: 1928.06 | H15: 72.03 | I15: 336.68 | J15: 0 | K15: 500.31 | L15: 65 | M15: =SUM(H15:L15) -> 974.02 | N15: =G15-M15 -> 954.04 | O15: =IFERROR(G15/F15,0) -> 0.36523205
A16: 46367 | B16: 2023 | C16: 4883 | D16: 0 | E16: 0 | F16: =B16+C16+D16+E16 -> 6906 | G16: 2548.11 | H16: 72.03 | I16: 336.68 | J16: 98 | K16: 500.31 | L16: 0 | M16: =SUM(H16:L16) -> 1007.02 | N16: =G16-M16 -> 1541.09 | O16: =IFERROR(G16/F16,0) -> 0.36897046
A17: 46368 | B17: 0 | C17: 0 | D17: 0 | E17: 0 | F17: =B17+C17+D17+E17 -> 0 | G17: 0 | H17: 72.03 | I17: 336.68 | J17: 0 | K17: 0 | L17: 0 | M17: =SUM(H17:L17) -> 408.71 | N17: =G17-M17 -> -408.71 | O17: =IFERROR(G17/F17,0) -> 0 | P17: Shop closed
A18: 46369 | B18: 1287 | C18: 2785 | D18: 0 | E18: 0 | F18: =B18+C18+D18+E18 -> 4072 | G18: 1533.18 | H18: 72.03 | I18: 336.68 | J18: 0 | K18: 500.31 | L18: 0 | M18: =SUM(H18:L18) -> 909.02 | N18: =G18-M18 -> 624.16 | O18: =IFERROR(G18/F18,0) -> 0.37651768
A19: 46370 | B19: 1928 | C19: 3521 | D19: 0 | E19: 0 | F19: =B19+C19+D19+E19 -> 5449 | G19: 1794.83 | H19: 72.03 | I19: 336.68 | J19: 0 | K19: 500.31 | L19: 0 | M19: =SUM(H19:L19) -> 909.02 | N19: =G19-M19 -> 885.81 | O19: =IFERROR(G19/F19,0) -> 0.32938704
A20: 46371 | B20: 903 | C20: 2537 | D20: 0 | E20: 0 | F20: =B20+C20+D20+E20 -> 3440 | G20: 1148.82 | H20: 72.03 | I20: 336.68 | J20: 0 | K20: 500.31 | L20: 0 | M20: =SUM(H20:L20) -> 909.02 | N20: =G20-M20 -> 239.8 | O20: =IFERROR(G20/F20,0) -> 0.3339593
A21: 46372 | B21: 1076 | C21: 2809 | D21: 0 | E21: 0 | F21: =B21+C21+D21+E21 -> 3885 | G21: 1256.8 | H21: 72.03 | I21: 336.68 | J21: 49 | K21: 500.31 | L21: 0 | M21: =SUM(H21:L21) -> 958.02 | N21: =G21-M21 -> 298.78 | O21: =IFERROR(G21/F21,0) -> 0.32350064
A22: 46373 | B22: 1184 | C22: 2552 | D22: 0 | E22: 0 | F22: =B22+C22+D22+E22 -> 3736 | G22: 1335.3 | H22: 72.03 | I22: 336.68 | J22: 0 | K22: 500.31 | L22: 0 | M22: =SUM(H22:L22) -> 909.02 | N22: =G22-M22 -> 426.28 | O22: =IFERROR(G22/F22,0) -> 0.35741435
A23: 46374 | B23: 2366 | C23: 5095 | D23: 0 | E23: 0 | F23: =B23+C23+D23+E23 -> 7461 | G23: 2672.12 | H23: 72.03 | I23: 336.68 | J23: 0 | K23: 500.31 | L23: 0 | M23: =SUM(H23:L23) -> 909.02 | N23: =G23-M23 -> 1763.1 | O23: =IFERROR(G23/F23,0) -> 0.35814502
A24: 46375 | B24: 2033 | C24: 4415 | D24: 0 | E24: 0 | F24: =B24+C24+D24+E24 -> 6448 | G24: 2264.26 | H24: 72.03 | I24: 336.68 | J24: 0 | K24: 500.31 | L24: 67 | M24: =SUM(H24:L24) -> 976.02 | N24: =G24-M24 -> 1288.24 | O24: =IFERROR(G24/F24,0) -> 0.35115695
A25: 46376 | B25: 1151 | C25: 2551 | D25: -1431 | E25: 0 | F25: =B25+C25+D25+E25 -> 2271 | G25: 817.54 | H25: 72.03 | I25: 336.68 | J25: 0 | K25: 500.31 | L25: 85 | M25: =SUM(H25:L25) -> 994.02 | N25: =G25-M25 -> -176.48 | O25: =IFERROR(G25/F25,0) -> 0.35999119
A26: 46377 | B26: 1813 | C26: 3342 | D26: 0 | E26: 0 | F26: =B26+C26+D26+E26 -> 5155 | G26: 1727.2 | H26: 72.03 | I26: 336.68 | J26: 35 | K26: 500.31 | L26: 0 | M26: =SUM(H26:L26) -> 944.02 | N26: =G26-M26 -> 783.18 | O26: =IFERROR(G26/F26,0) -> 0.33505335
A27: 46378 | B27: 1198 | C27: 2737 | D27: 0 | E27: 0 | F27: =B27+C27+D27+E27 -> 3935 | G27: 1479.39 | H27: 72.03 | I27: 336.68 | J27: 23 | K27: 500.31 | L27: 0 | M27: =SUM(H27:L27) -> 932.02 | N27: =G27-M27 -> 547.37 | O27: =IFERROR(G27/F27,0) -> 0.3759568
A28: 46379 | B28: 1123 | C28: 2550 | D28: 0 | E28: 0 | F28: =B28+C28+D28+E28 -> 3673 | G28: 1232.35 | H28: 72.03 | I28: 336.68 | J28: 21 | K28: 500.31 | L28: 0 | M28: =SUM(H28:L28) -> 930.02 | N28: =G28-M28 -> 302.33 | O28: =IFERROR(G28/F28,0) -> 0.33551593
A29: 46380 | B29: 1170 | C29: 2767 | D29: 0 | E29: 0 | F29: =B29+C29+D29+E29 -> 3937 | G29: 1268.88 | H29: 72.03 | I29: 336.68 | J29: 0 | K29: 500.31 | L29: 19 | M29: =SUM(H29:L29) -> 928.02 | N29: =G29-M29 -> 340.86 | O29: =IFERROR(G29/F29,0) -> 0.32229616
... A36: 46387 | B36: 1333 | C36: 3495 | D36: 0 | E36: 0 | F36: =B36+C36+D36+E36 -> 4828 | G36: 1588.02 | H36: 72.03 | I36: 336.68 | J36: 0 | K36: 500.31 | L36: 0 | M36: =SUM(H36:L36) -> 909.02 | N36: =G36-M36 -> 679 | O36: =IFERROR(G36/F36,0) -> 0.32891881
A38: TOTAL | B38: =SUM(B6:B36) -> 45322 | C38: =SUM(C6:C36) -> 97677 | D38: =SUM(D6:D36) -> -1431 | E38: =SUM(E6:E36) -> 507 | F38: =SUM(F6:F36) -> 142075 | G38: =SUM(G6:G36) -> 49396.4 | H38: =SUM(H6:H36) -> 2232.93 | I38: =SUM(I6:I36) -> 10437.08 | ... N38: =SUM(N6:N36) -> 20899.09 | O38: =IFERROR(G38/F38,0) -> 0.34767834

Sheet January 2027
A1: January 2027 — Daily Sales & P&L
A2: Sample data for this demo. Yellow cells are editable — swap in your own shop's numbers to reuse this template.
A4: Date | B4: Cash Sales | C4: GPay Sales | D4: Sales Return | E4: Credit Redeemed | F4: Total Sales | G4: Gross Profit | H4: Electric Bill | I4: Shop Rent | J4: Shop Expense | K4: Salary | L4: Donation | M4: Total Expense | N4: Net P&L | O4: Margin % | P4: Notes
A6: 46388 | B6: 1436 | C6: 2881 | D6: 0 | E6: 0 | F6: =B6+C6+D6+E6 -> 4317 | G6: 1338.33 | H6: 70.98 | I6: 344.9 | J6: 0 | K6: 627.01 | L6: 0 | M6: =SUM(H6:L6) -> 1042.89 | N6: =G6-M6 -> 295.44 | O6: =IFERROR(G6/F6,0) -> 0.3100139
A7: 46389 | B7: 1251 | C7: 2594 | D7: 0 | E7: 0 | F7: =B7+C7+D7+E7 -> 3845 | G7: 1205.37 | H7: 70.98 | I7: 344.9 | J7: 0 | K7: 627.01 | L7: 0 | M7: =SUM(H7:L7) -> 1042.89 | N7: =G7-M7 -> 162.48 | O7: =IFERROR(G7/F7,0) -> 0.31349025
A8: 46390 | B8: 869 | C8: 1623 | D8: 0 | E8: 0 | F8: =B8+C8+D8+E8 -> 2492 | G8: 891.27 | H8: 70.98 | I8: 344.9 | J8: 0 | K8: 627.01 | L8: 0 | M8: =SUM(H8:L8) -> 1042.89 | N8: =G8-M8 -> -151.62 | O8: =IFERROR(G8/F8,0) -> 0.35765249
A9: 46391 | B9: 737 | C9: 1465 | D9: 0 | E9: 0 | F9: =B9+C9+D9+E9 -> 2202 | G9: 805.97 | H9: 70.98 | I9: 344.9 | J9: 7 | K9: 627.01 | L9: 0 | M9: =SUM(H9:L9) -> 1049.89 | N9: =G9-M9 -> -243.92 | O9: =IFERROR(G9/F9,0) -> 0.36601726
A10: 46392 | B10: 845 | C10: 1666 | D10: 0 | E10: 0 | F10: =B10+C10+D10+E10 -> 2511 | G10: 884.1 | H10: 70.98 | I10: 344.9 | J10: 0 | K10: 627.01 | L10: 0 | M10: =SUM(H10:L10) -> 1042.89 | N10: =G10-M10 -> -158.79 | O10: =IFERROR(G10/F10,0) -> 0.3520908
A11: 46393 | B11: 1200 | C11: 2270 | D11: 0 | E11: 0 | F11: =B11+C11+D11+E11 -> 3470 | G11: 1179.26 | H11: 70.98 | I11: 344.9 | J11: 0 | K11: 627.01 | L11: 0 | M11: =SUM(H11:L11) -> 1042.89 | N11: =G11-M11 -> 136.37 | O11: =IFERROR(G11/F11,0) -> 0.33984438
A12: 46394 | B12: 1212 | C12: 1868 | D12: 0 | E12: 0 | F12: =B12+C12+D12+E12 -> 3080 | G12: 1043 | H12: 70.98 | I12: 344.9 | J12: 0 | K12: 627.01 | L12: 0 | M12: =SUM(H12:L12) -> 1042.89 | N12: =G12-M12 -> 0.11 | O12: =IFERROR(G12/F12,0) -> 0.33863636
A13: 46395 | B13: 1118 | C13: 2678 | D13: 0 | E13: 0 | F13: =B13+C13+D13+E13 -> 3796 | G13: 1160.96 | H13: 70.98 | I13: 344.9 | J13: 66 | K13: 627.01 | L13: 0 | M13: =SUM(H13:L13) -> 1108.89 | N13: =G13-M13 -> 52.07 | O13: =IFERROR(G13/F13,0) -> 0.30583772
A14: 46396 | B14: 1193 | C14: 3059 | D14: 0 | E14: 0 | F14: =B14+C14+D14+E14 -> 4252 | G14: 1481.96 | H14: 70.98 | I14: 344.9 | J14: 0 | K14: 627.01 | L14: 0 | M14: =SUM(H14:L14) -> 1042.89 | N14: =G14-M14 -> 439.07 | O14: =IFERROR(G14/F14,0) -> 0.34853246
A15: 46397 | B15: 987 | C15: 1754 | D15: 0 | E15: 2431 | F15: =B15+C15+D15+E15 -> 5172 | G15: 1955.17 | H15: 70.98 | I15: 344.9 | J15: 56 | K15: 627.01 | L15: 0 | M15: =SUM(H15:L15) -> 1098.89 | N15: =G15-M15 -> 856.28 | O15: =IFERROR(G15/F15,0) -> 0.37802978
A16: 46398 | B16: 651 | C16: 1533 | D16: 0 | E16: 0 | F16: =B16+C16+D16+E16 -> 2184 | G16: 736.7 | H16: 70.98 | I16: 344.9 | J16: 0 | K16: 627.01 | L16: 0 | M16: =SUM(H16:L16) -> 1042.89 | N16: =G16-M16 -> -306.19 | O16: =IFERROR(G16/F16,0) -> 0.33731685
A17: 46399 | B17: 908 | C17: 2524 | D17: 0 | E17: 0 | F17: =B17+C17+D17+E17 -> 3432 | G17: 1109.28 | H17: 70.98 | I17: 344.9 | J17: 0 | K17: 627.01 | L17: 0 | M17: =SUM(H17:L17) -> 1042.89 | N17: =G17-M17 -> 66.39 | O17: =IFERROR(G17/F17,0) -> 0.32321678
